Workbook
Name AOQ: #REF!
Name def: #REF!
Name ReimburseAmt: #REF!
Name RegularHours: #REF!
Name abc: #REF!
Name WorkHours: #REF!
Name HolidayHours: #REF!
Name asa: #REF!
Name VacationHours: #REF!
Name ABCD: #REF!
Name OvertimeHours: #REF!
Name SickHours: #REF!

Sheet SUMMARY
A1: TOTALS | B1: =SUM(B4:B367) -> 11 | C1: =SUM(C4:C367) -> 0 | D1: =SUM(D4:D367) -> 11.5 | E1: =SUM(B1:D1) -> 22.5
A2: Date | B2: ="529" -> 529 | C2: ABLE | D2: SECURECHOICE | E2: DESCRIPTION
A3: 46023 | B3: =IF('529'!F4>0,'529'!F4,0) -> 0 | C3: =IF(ABLE!F4>0,ABLE!F4,0) -> 0 | D3: =IF(SECURECHOICE!F4>0,SECURECHOICE!F4,0) -> 0 | E3: =IF(B3>0," 529: "&'529'!G4,"")&IF(C3>0," ABLE: "&ABLE!G4,"")&IF(D3>0," SC:"&SECURECHOICE!G4,"")
A4: =A3+1 -> 46024 | B4: =IF('529'!F5>0,'529'!F5,0) -> 0 | C4: =IF(ABLE!F5>0,ABLE!F5,0) -> 0 | D4: =IF(SECURECHOICE!F5>0,SECURECHOICE!F5,0) -> 0 | E4: =IF(B4>0," 529: "&'529'!G5,"")&IF(C4>0," ABLE: "&ABLE!G5,"")&IF(D4>0," SC:"&SECURECHOICE!G5,"")
A5: =A4+1 -> 46025 | B5: =IF('529'!F6>0,'529'!F6,0) -> 0 | C5: =IF(ABLE!F6>0,ABLE!F6,0) -> 0 | D5: =IF(SECURECHOICE!F6>0,SECURECHOICE!F6,0) -> 0 | E5: =IF(B5>0," 529: "&'529'!G6,"")&IF(C5>0," ABLE: "&ABLE!G6,"")&IF(D5>0," SC:"&SECURECHOICE!G6,"")
A6: =A5+1 -> 46026 | B6: =IF('529'!F7>0,'529'!F7,0) -> 0 | C6: =IF(ABLE!F7>0,ABLE!F7,0) -> 0 | D6: =IF(SECURECHOICE!F7>0,SECURECHOICE!F7,0) -> 0 | E6: =IF(B6>0," 529: "&'529'!G7,"")&IF(C6>0," ABLE: "&ABLE!G7,"")&IF(D6>0," SC:"&SECURECHOICE!G7,"")
A7: =A6+1 -> 46027 | B7: =IF('529'!F8>0,'529'!F8,0) -> 0 | C7: =IF(ABLE!F8>0,ABLE!F8,0) -> 0 | D7: =IF(SECURECHOICE!F8>0,SECURECHOICE!F8,0) -> 0 | E7: =IF(B7>0," 529: "&'529'!G8,"")&IF(C7>0," ABLE: "&ABLE!G8,"")&IF(D7>0," SC:"&SECURECHOICE!G8,"")
A8: =A7+1 -> 46028 | B8: =IF('529'!F9>0,'529'!F9,0) -> 0 | C8: =IF(ABLE!F9>0,ABLE!F9,0) -> 0 | D8: =IF(SECURECHOICE!F9>0,SECURECHOICE!F9,0) -> 0 | E8: =IF(B8>0," 529: "&'529'!G9,"")&IF(C8>0," ABLE: "&ABLE!G9,"")&IF(D8>0," SC:"&SECURECHOICE!G9,"")
A9: =A8+1 -> 46029 | B9: =IF('529'!F10>0,'529'!F10,0) -> 0 | C9: =IF(ABLE!F10>0,ABLE!F10,0) -> 0 | D9: =IF(SECURECHOICE!F10>0,SECURECHOICE!F10,0) -> 0 | E9: =IF(B9>0," 529: "&'529'!G10,"")&IF(C9>0," ABLE: "&ABLE!G10,"")&IF(D9>0," SC:"&SECURECHOICE!G10,"")
A10: =A9+1 -> 46030 | B10: =IF('529'!F11>0,'529'!F11,0) -> 0 | C10: =IF(ABLE!F11>0,ABLE!F11,0) -> 0 | D10: =IF(SECURECHOICE!F11>0,SECURECHOICE!F11,0) -> 0 | E10: =IF(B10>0," 529: "&'529'!G11,"")&IF(C10>0," ABLE: "&ABLE!G11,"")&IF(D10>0," SC:"&SECURECHOICE!G11,"")
A11: =A10+1 -> 46031 | B11: =IF('529'!F12>0,'529'!F12,0) -> 0 | C11: =IF(ABLE!F12>0,ABLE!F12,0) -> 0 | D11: =IF(SECURECHOICE!F12>0,SECURECHOICE!F12,0) -> 0 | E11: =IF(B11>0," 529: "&'529'!G12,"")&IF(C11>0," ABLE: "&ABLE!G12,"")&IF(D11>0," SC:"&SECURECHOICE!G12,"")
A12: =A11+1 -> 46032 | B12: =IF('529'!F13>0,'529'!F13,0) -> 0 | C12: =IF(ABLE!F13>0,ABLE!F13,0) -> 0 | D12: =IF(SECURECHOICE!F13>0,SECURECHOICE!F13,0) -> 0 | E12: =IF(B12>0," 529: "&'529'!G13,"")&IF(C12>0," ABLE: "&ABLE!G13,"")&IF(D12>0," SC:"&SECURECHOICE!G13,"")
A13: =A12+1 -> 46033 | B13: =IF('529'!F14>0,'529'!F14,0) -> 0 | C13: =IF(ABLE!F14>0,ABLE!F14,0) -> 0 | D13: =IF(SECURECHOICE!F14>0,SECURECHOICE!F14,0) -> 0 | E13: =IF(B13>0," 529: "&'529'!G14,"")&IF(C13>0," ABLE: "&ABLE!G14,"")&IF(D13>0," SC:"&SECURECHOICE!G14,"")
A14: =A13+1 -> 46034 | B14: =IF('529'!F15>0,'529'!F15,0) -> 0 | C14: =IF(ABLE!F15>0,ABLE!F15,0) -> 0 | D14: =IF(SECURECHOICE!F15>0,SECURECHOICE!F15,0) -> 0 | E14: =IF(B14>0," 529: "&'529'!G15,"")&IF(C14>0," ABLE: "&ABLE!G15,"")&IF(D14>0," SC:"&SECURECHOICE!G15,"")
A15: =A14+1 -> 46035 | B15: =IF('529'!F16>0,'529'!F16,0) -> 0 | C15: =IF(ABLE!F16>0,ABLE!F16,0) -> 0 | D15: =IF(SECURECHOICE!F16>0,SECURECHOICE!F16,0) -> 0 | E15: =IF(B15>0," 529: "&'529'!G16,"")&IF(C15>0," ABLE: "&ABLE!G16,"")&IF(D15>0," SC:"&SECURECHOICE!G16,"")
... A367: =A366+1 -> 46387 | B367: =IF('529'!F368>0,'529'!F368,0) -> 0 | C367: =IF(ABLE!F368>0,ABLE!F368,0) -> 0 | D367: =IF(SECURECHOICE!F368>0,SECURECHOICE!F368,0) -> 0 | E367: =IF(B367>0," 529: "&'529'!G368,"")&IF(C367>0," ABLE: "&ABLE!G368,"")&IF(D367>0," SC:"&SECURECHOICE!G368,"")

Sheet 529
A1: TOTALS | B1: =SUM(B4:B368) -> 2 | C1: =SUM(C4:C368) -> 2.5 | D1: =SUM(D4:D368) -> 1.5 | E1: =SUM(E4:E368) -> 5 | F1: =SUM(F4:F368) -> 11
B2: GEORGE | D2: KAPREL | F2: TOTAL | G2: DESCRIPTION
A3: Date | B3: Meetings | C3: Offline Work | D3: Meetings | E3: Offline Work | F3: Total Hours
A4: 46023 | F4: =SUM(B4:E4) -> 0 | G4: =IF(F4>0,"Describe work performed","")
A5: =A4+1 -> 46024 | F5: =SUM(B5:E5) -> 0 | G5: =IF(F5>0,"Describe work performed","")
A6: =A5+1 -> 46025 | F6: =SUM(B6:E6) -> 0 | G6: =IF(F6>0,"Describe work performed","")
A7: =A6+1 -> 46026 | F7: =SUM(B7:E7) -> 0 | G7: =IF(F7>0,"Describe work performed","")
A8: =A7+1 -> 46027 | F8: =SUM(B8:E8) -> 0 | G8: =IF(F8>0,"Describe work performed","")
A9: =A8+1 -> 46028 | F9: =SUM(B9:E9) -> 0 | G9: =IF(F9>0,"Describe work performed","")
A10: =A9+1 -> 46029 | F10: =SUM(B10:E10) -> 0 | G10: =IF(F10>0,"Describe work performed","")
A11: =A10+1 -> 46030 | F11: =SUM(B11:E11) -> 0 | G11: =IF(F11>0,"Describe work performed","")
A12: =A11+1 -> 46031 | F12: =SUM(B12:E12) -> 0 | G12: =IF(F12>0,"Describe work performed","")
A13: =A12+1 -> 46032 | F13: =SUM(B13:E13) -> 0 | G13: =IF(F13>0,"Describe work performed","")
A14: =A13+1 -> 46033 | F14: =SUM(B14:E14) -> 0 | G14: =IF(F14>0,"Describe work performed","")
A15: =A14+1 -> 46034 | F15: =SUM(B15:E15) -> 0 | G15: =IF(F15>0,"Describe work performed","")
A16: =A15+1 -> 46035 | F16: =SUM(B16:E16) -> 0 | G16: =IF(F16>0,"Describe work performed","")
... A23: =A22+1 -> 46042 | F23: =SUM(B23:E23) -> 0 | G23: =IF(F23>0,"Describe work performed","")
A24: =A23+1 -> 46043 | B24: 0.5 | F24: =SUM(B24:E24) -> 0.5 | G24: IL & TIAA Call Center review
A25: =A24+1 -> 46044 | F25: =SUM(B25:E25) -> 0 | G25: =IF(F25>0,"Describe work performed","")
A26: =A25+1 -> 46045 | F26: =SUM(B26:E26) -> 0 | G26: =IF(F26>0,"Describe work performed","")
A27: =A26+1 -> 46046 | F27: =SUM(B27:E27) -> 0 | G27: =IF(F27>0,"Describe work performed","")
A28: =A27+1 -> 46047 | F28: =SUM(B28:E28) -> 0 | G28: =IF(F28>0,"Describe work performed","")
A29: =A28+1 -> 46048 | F29: =SUM(B29:E29) -> 0 | G29: =IF(F29>0,"Describe work performed","")
A30: =A29+1 -> 46049 | F30: =SUM(B30:E30) -> 0 | G30: =IF(F30>0,"Describe work performed","")
A31: =A30+1 -> 46050 | F31: =SUM(B31:E31) -> 0 | G31: =IF(F31>0,"Describe work performed","")
A32: =A31+1 -> 46051 | F32: =SUM(B32:E32) -> 0 | G32: =IF(F32>0,"Describe work performed","")
A33: =A32+1 -> 46052 | F33: =SUM(B33:E33) -> 0 | G33: =IF(F33>0,"Describe work performed","")
A34: =A33+1 -> 46053 | F34: =SUM(B34:E34) -> 0 | G34: =IF(F34>0,"Describe work performed","")
A35: =A34+1 -> 46054 | F35: =SUM(B35:E35) -> 0 | G35: =IF(F35>0,"Describe work performed","")
A36: =A35+1 -> 46055 | F36: =SUM(B36:E36) -> 0 | G36: =IF(F36>0,"Describe work performed","")
... A59: =A58+1 -> 46078 | F59: =SUM(B59:E59) -> 0 | G59: =IF(F59>0,"Describe work performed","")
A60: =A59+1 -> 46079 | F60: =SUM(B60:E60) -> 0
A61: =A60+1 -> 46080 | C61: 0.5 | F61: =SUM(B61:E61) -> 0.5 | G61: Review Omnibus questionnaire
A62: =A61+1 -> 46081 | C62: 2 | F62: =SUM(B62:E62) -> 2 | G62: Review Due Diligence Questionnaire & SOC Rpts
A63: =A62+1 -> 46082 | E63: 2 | F63: =SUM(B63:E63) -> 2 | G63: Review TIAA DD responses
A64: =A63+1 -> 46083 | F64: =SUM(B64:E64) -> 0 | G64: =IF(F64>0,"Describe work performed","")
A65: =A64+1 -> 46084 | F65: =SUM(B65:E65) -> 0 | G65: =IF(F65>0,"Describe work performed","")
A66: =A65+1 -> 46085 | F66: =SUM(B66:E66) -> 0 | G66: =IF(F66>0,"Describe work performed","")
A67: =A66+1 -> 46086 | F67: =SUM(B67:E67) -> 0 | G67: =IF(F67>0,"Describe work performed","")
A68: =A67+1 -> 46087 | E68: 3 | F68: =SUM(B68:E68) -> 3 | G68: Review NT SOC Reports
...

Sheet ABLE
A1: TOTALS | B1: =SUM(B4:B368) -> 0 | C1: =SUM(C4:C368) -> 0 | D1: =SUM(D4:D368) -> 0 | E1: =SUM(E4:E368) -> 0 | F1: =SUM(F4:F368) -> 0
B2: GEORGE | D2: KAPREL | F2: TOTAL | G2: DESCRIPTION
A3: Date | B3: Meetings | C3: Offline Work | D3: Meetings | E3: Offline Work | F3: Total Hours
A4: 46023 | F4: =SUM(B4:E4) -> 0 | G4: =IF(F4>0,"Describe work performed","")
A5: =A4+1 -> 46024 | F5: =SUM(B5:E5) -> 0 | G5: =IF(F5>0,"Describe work performed","")
A6: =A5+1 -> 46025 | F6: =SUM(B6:E6) -> 0 | G6: =IF(F6>0,"Describe work performed","")
A7: =A6+1 -> 46026 | F7: =SUM(B7:E7) -> 0 | G7: =IF(F7>0,"Describe work performed","")
A8: =A7+1 -> 46027 | F8: =SUM(B8:E8) -> 0 | G8: =IF(F8>0,"Describe work performed","")
A9: =A8+1 -> 46028 | F9: =SUM(B9:E9) -> 0 | G9: =IF(F9>0,"Describe work performed","")
A10: =A9+1 -> 46029 | F10: =SUM(B10:E10) -> 0 | G10: =IF(F10>0,"Describe work performed","")
A11: =A10+1 -> 46030 | F11: =SUM(B11:E11) -> 0 | G11: =IF(F11>0,"Describe work performed","")
A12: =A11+1 -> 46031 | F12: =SUM(B12:E12) -> 0 | G12: =IF(F12>0,"Describe work performed","")
A13: =A12+1 -> 46032 | F13: =SUM(B13:E13) -> 0 | G13: =IF(F13>0,"Describe work performed","")
A14: =A13+1 -> 46033 | F14: =SUM(B14:E14) -> 0 | G14: =IF(F14>0,"Describe work performed","")
A15: =A14+1 -> 46034 | F15: =SUM(B15:E15) -> 0 | G15: =IF(F15>0,"Describe work performed","")
A16: =A15+1 -> 46035 | F16: =SUM(B16:E16) -> 0 | G16: =IF(F16>0,"Describe work performed","")
... A368: =A367+1 -> 46387 | F368: =SUM(B368:E368) -> 0 | G368: =IF(F368>0,"Describe work performed","")

Sheet SECURECHOICE
A1: TOTALS | B1: =SUM(B4:B368) -> 3 | C1: =SUM(C4:C368) -> 2.5 | D1: =SUM(D4:D368) -> 2.5 | E1: =SUM(E4:E368) -> 3.5 | F1: =SUM(F4:F368) -> 11.5
B2: GEORGE | D2: KAPREL | F2: TOTAL | G2: DESCRIPTION
A3: Date | B3: Meetings | C3: Offline Work | D3: Meetings | E3: Offline Work | F3: Total Hours
A4: 46023 | F4: =SUM(B4:E4) -> 0 | G4: =IF(F4>0,"Describe work performed","")
A5: =A4+1 -> 46024 | F5: =SUM(B5:E5) -> 0 | G5: =IF(F5>0,"Describe work performed","")
A6: =A5+1 -> 46025 | F6: =SUM(B6:E6) -> 0 | G6: =IF(F6>0,"Describe work performed","")
A7: =A6+1 -> 46026 | F7: =SUM(B7:E7) -> 0 | G7: =IF(F7>0,"Describe work performed","")
A8: =A7+1 -> 46027 | F8: =SUM(B8:E8) -> 0 | G8: =IF(F8>0,"Describe work performed","")
A9: =A8+1 -> 46028 | F9: =SUM(B9:E9) -> 0 | G9: =IF(F9>0,"Describe work performed","")
A10: =A9+1 -> 46029 | F10: =SUM(B10:E10) -> 0 | G10: =IF(F10>0,"Describe work performed","")
A11: =A10+1 -> 46030 | F11: =SUM(B11:E11) -> 0 | G11: =IF(F11>0,"Describe work performed","")
A12: =A11+1 -> 46031 | F12: =SUM(B12:E12) -> 0 | G12: =IF(F12>0,"Describe work performed","")
A13: =A12+1 -> 46032 | F13: =SUM(B13:E13) -> 0 | G13: =IF(F13>0,"Describe work performed","")
A14: =A13+1 -> 46033 | F14: =SUM(B14:E14) -> 0 | G14: =IF(F14>0,"Describe work performed","")
A15: =A14+1 -> 46034 | F15: =SUM(B15:E15) -> 0 | G15: =IF(F15>0,"Describe work performed","")
A16: =A15+1 -> 46035 | F16: =SUM(B16:E16) -> 0 | G16: =IF(F16>0,"Describe work performed","")
... A59: =A58+1 -> 46078 | F59: =SUM(B59:E59) -> 0 | G59: =IF(F59>0,"Describe work performed","")
A60: =A59+1 -> 46079 | B60: 0.5 | D60: 0.5 | F60: =SUM(B60:E60) -> 1 | G60: Weekly Conversion call
A61: =A60+1 -> 46080 | F61: =SUM(B61:E61) -> 0 | G61: =IF(F61>0,"Describe work performed","")
A62: =A61+1 -> 46081 | F62: =SUM(B62:E62) -> 0 | G62: =IF(F62>0,"Describe work performed","")
A63: =A62+1 -> 46082 | F63: =SUM(B63:E63) -> 0 | G63: =IF(F63>0,"Describe work performed","")
A64: =A63+1 -> 46083 | F64: =SUM(B64:E64) -> 0 | G64: =IF(F64>0,"Describe work performed","")
A65: =A64+1 -> 46084 | F65: =SUM(B65:E65) -> 0 | G65: =IF(F65>0,"Describe work performed","")
A66: =A65+1 -> 46085 | F66: =SUM(B66:E66) -> 0 | G66: =IF(F66>0,"Describe work performed","")
A67: =A66+1 -> 46086 | B67: 1 | D67: 1 | F67: =SUM(B67:E67) -> 2 | G67: Weekly Conversion call
A68: =A67+1 -> 46087 | E68: 3.5 | F68: =SUM(B68:E68) -> 3.5 | G68: Vestwell DD document + SOC review
A69: =A68+1 -> 46088 | C69: 2.5 | F69: =SUM(B69:E69) -> 2.5 | G69: Vestwell DD document
A70: =A69+1 -> 46089 | F70: =SUM(B70:E70) -> 0 | G70: =IF(F70>0,"Describe work performed","")
A71: =A70+1 -> 46090 | F71: =SUM(B71:E71) -> 0 | G71: =IF(F71>0,"Describe work performed","")
A72: =A71+1 -> 46091 | B72: 1 | D72: 1 | F72: =SUM(B72:E72) -> 2 | G72: Vestwell DD prep call
A73: =A72+1 -> 46092 | F73: =SUM(B73:E73) -> 0 | G73: =IF(F73>0,"Describe work performed","")
A74: =A73+1 -> 46093 | B74: 0.5 | F74: =SUM(B74:E74) -> 0.5 | G74: Weekly Conversion call GB only
A75: =A74+1 -> 46094 | F75: =SUM(B75:E75) -> 0 | G75: =IF(F75>0,"Describe work performed","")
A76: =A75+1 -> 46095 | F76: =SUM(B76:E76) -> 0 | G76: =IF(F76>0,"Describe work performed","")
A77: =A76+1 -> 46096 | F77: =SUM(B77:E77) -> 0 | G77: =IF(F77>0,"Describe work performed","")
A78: =A77+1 -> 46097 | F78: =SUM(B78:E78) -> 0 | G78: =IF(F78>0,"Describe work performed","")
A79: =A78+1 -> 46098 | F79: =SUM(B79:E79) -> 0 | G79: =IF(F79>0,"Describe work performed","")
A80: =A79+1 -> 46099 | F80: =SUM(B80:E80) -> 0 | G80: =IF(F80>0,"Describe work performed","")
A81: =A80+1 -> 46100 | F81: =SUM(B81:E81) -> 0 | G81: =IF(F81>0,"Describe work performed","")
A82: =A81+1 -> 46101 | F82: =SUM(B82:E82) -> 0 | G82: =IF(F82>0,"Describe work performed","")
...
